Workbook

Sheet Inicio
A1: EDA — Rendimiento estudiantil (versión Excel)
A2: Análisis exploratorio sobre la base ya limpia (student_performance_limpio).
A4: Mapa del libro
A5: Datos | B5: Base limpia de estudiantes (una fila por estudiante).
A6: Calidad | B6: Revisa nulos, duplicados y valores fuera de rango (Paso 2).
A7: Univariado | B7: Estadísticas de la nota final y conteo por nota (Paso 3).
A8: Bivariado | B8: Nota promedio por educación de padres y por género (Paso 4).
A9: Correlacion | B9: Relación de estudio/nota previa/asistencia con la nota final (Paso 5).
A10: Conclusiones | B10: Hallazgos e hipótesis (Paso 6).
A12: Leyenda de colores
A13: Texto azul | B13: Dato de entrada (la base). Se puede reemplazar por otra base con las mismas columnas.
A14: Texto negro | B14: Resultado calculado con fórmula.
A15: Celda amarilla | B15: Conclusión escrita por la estudiante.

Sheet Datos
A1: student_id | B1: gender | C1: parental_education | D1: Internet_Access | E1: extracurricular_activities | F1: part_time_job | G1: final_grade | H1: enrollment_date_clean | I1: study_time_hours | J1: attendance_percent | K1: sleep_hours | L1: previous_grade | M1: final_exam_score
A2: 781 | B2: Female | C2: Masters | D2: Yes | E2: Yes | F2: Yes | G2: A | H2: 45019 | I2: 6.3 | J2: 97.4 | K2: 7.3 | L2: 92.7 | M2: 100
A3: 543 | B3: Female | C3: PhD | D3: Yes | E3: No | F3: No | G3: F | H3: 45432 | I3: 2 | J3: 74.8 | K3: 6.2 | L3: 48.3 | M3: 56.6
A4: 34 | B4: Female | C4: Bachelors | D4: Yes | E4: Yes | F4: No | G4: C | H4: 45302 | I4: 4.7 | J4: 92.3 | K4: 4.7 | L4: 62.8 | M4: 74.2
A5: 459 | B5: Female | C5: Masters | D5: Yes | E5: Yes | F5: No | G5: C | H5: 45294 | I5: 3.3 | J5: 82.9 | K5: 6.5 | L5: 77.6 | M5: 74.8
A6: 100 | B6: Male | C6: Masters | D6: Yes | E6: Yes | F6: No | G6: C | H6: 45308 | I6: 6.2 | J6: 74.7 | K6: 5 | L6: 50.6 | M6: 76
A7: 311 | B7: Male | C7: PhD | D7: Yes | E7: No | F7: No | G7: A | H7: 45423 | I7: 6 | J7: 85.3 | K7: 7.1 | L7: 94.9 | M7: 100
A8: 756 | B8: Male | C8: High School | D8: Yes | E8: No | F8: Yes | G8: D | H8: 45065 | I8: 1.2 | J8: 82.6 | K8: 5 | L8: 93.1 | M8: 65.8
A9: 184 | B9: Female | C9: High School | D9: No | E9: No | F9: Yes | G9: C | H9: 45220 | I9: 2.3 | J9: 73.9 | K9: 4.7 | L9: 85.8 | M9: 70.2
A10: 323 | B10: Male | C10: High School | D10: No | E10: No | F10: No | G10: B | H10: 44969 | I10: 7 | J10: 78.3 | K10: 7.2 | L10: 69.1 | M10: 83.4
A11: 174 | B11: Female | C11: PhD | D11: Yes | E11: Yes | F11: Yes | G11: D | H11: 44997 | I11: 4.5 | J11: 96.1 | K11: 8.5 | L11: 35.9 | M11: 61
A12: 355 | B12: Male | C12: Bachelors | D12: Yes | E12: No | F12: Yes | G12: B | H12: 44995 | I12: 5 | J12: 87.7 | K12: 6.7 | L12: 90.9 | M12: 87.8
A13: 647 | B13: Male | C13: Bachelors | D13: Yes | E13: Yes | F13: No | G13: D | H13: 45403 | I13: 5.6 | J13: 88.5 | K13: 5.5 | L13: 40.8 | M13: 61.5
A14: 868 | B14: Female | C14: Bachelors | D14: Yes | E14: No | F14: Yes | G14: B | H14: 45503 | I14: 2.6 | J14: 73.9 | K14: 8.9 | L14: 83.3 | M14: 73
A15: 344 | B15: Male | C15: PhD | D15: Yes | E15: No | F15: Yes | G15: D | I15: 3.5 | J15: 66.7 | K15: 6.7 | L15: 92.2 | M15: 74.1
A16: 125 | B16: Male | C16: PhD | D16: Yes | E16: Yes | F16: No | G16: B | H16: 45088 | I16: 4.8 | J16: 68.9 | K16: 6.7 | L16: 65 | M16: 82.7
A17: 673 | B17: Female | C17: High School | D17: Yes | E17: No | F17: No | G17: C | H17: 45026 | I17: 6.2 | J17: 82 | K17: 5.1 | L17: 38 | M17: 72.9
A18: 610 | B18: Female | D18: Yes | E18: Yes | F18: Yes | G18: C | H18: 44944 | I18: 6.1 | J18: 73.8 | K18: 8.8 | L18: 45.3 | M18: 79.8
A19: 812 | B19: Male | C19: PhD | D19: Yes | E19: Yes | F19: No | G19: C | H19: 45213 | I19: 3.5 | J19: 76.4 | K19: 4.2 | L19: 78.8 | M19: 74.2
A20: 574 | B20: Male | D20: Yes | E20: No | F20: Yes | G20: F | H20: 44961 | I20: 2.7 | J20: 90.1 | K20: 7.1 | L20: 37.9 | M20: 57.8
A21: 547 | B21: Male | C21: High School | D21: Yes | E21: No | F21: No | G21: C | H21: 45480 | I21: 1.9 | J21: 82 | K21: 7.6 | L21: 82.3 | M21: 74.1
A22: 942 | B22: Female | D22: No | E22: No | F22: No | G22: B | H22: 45222 | I22: 5.7 | J22: 89.8 | K22: 5 | L22: 71.3 | M22: 80.5
A23: 725 | B23: Female | C23: Bachelors | D23: Yes | E23: Yes | F23: No | G23: D | H23: 45296 | I23: 3.4 | J23: 71 | K23: 4.6 | L23: 88.5 | M23: 62.6
A24: 198 | B24: Female | C24: Masters | D24: Yes | E24: Yes | F24: Yes | G24: C | H24: 45508 | I24: 3.4 | J24: 77.1 | K24: 6.3 | L24: 44.2 | M24: 71.5
A25: 645 | B25: Female | C25: Bachelors | D25: Yes | E25: No | F25: Yes | G25: D | H25: 45506 | I25: 1 | J25: 88.8 | K25: 7.6 | L25: 47.1 | M25: 69.8
A26: 583 | B26: Female | C26: PhD | D26: Yes | E26: Yes | F26: No | G26: D | H26: 45475 | I26: 3.6 | J26: 67.2 | K26: 5.3 | L26: 71.1 | M26: 65.2
A27: 384 | B27: Male | D27: No | E27: Yes | F27: No | G27: B | H27: 44941 | I27: 6.9 | J27: 92.4 | K27: 8.7 | L27: 62.1 | M27: 74.1
A28: 546 | B28: Male | C28: Masters | D28: Yes | E28: No | F28: Yes | G28: A | H28: 45044 | I28: 4.8 | J28: 97.2 | K28: 6 | L28: 87.8 | M28: 94.5
A29: 662 | B29: Male | C29: High School | D29: Yes | E29: Yes | F29: No | G29: C | H29: 45380 | I29: 5 | J29: 73.4 | K29: 7.9 | L29: 58.1 | M29: 72.1
A30: 418 | B30: Male | C30: High School | D30: Yes | E30: No | F30: Yes | G30: F | H30: 45301 | I30: 1.1 | J30: 73.7 | K30: 4.3 | L30: 74.7 | M30: 58.9
A31: 463 | B31: Female | C31: Bachelors | D31: Yes | E31: Yes | F31: Yes | G31: B | H31: 45653 | I31: 4 | J31: 81.1 | K31: 8.8 | L31: 82.3 | M31: 81.6
A32: 222 | B32: Female | C32: High School | D32: Yes | E32: No | F32: No | G32: F | H32: 45171 | I32: 1 | J32: 81.6 | K32: 7.8 | L32: 66.2 | M32: 57.5
A33: 172 | B33: Male | C33: High School | D33: Yes | E33: No | F33: Yes | G33: F | H33: 45475 | I33: 1.6 | J33: 81.4 | K33: 6.7 | L33: 51.4 | M33: 57.9
A34: 813 | B34: Male | C34: PhD | D34: Yes | E34: Yes | F34: Yes | G34: C | H34: 45573 | I34: 3.3 | J34: 74.7 | K34: 6.1 | L34: 74.5 | M34: 73.1
A35: 423 | B35: Male | C35: Masters | D35: Yes | E35: No | F35: No | G35: C | H35: 45027 | I35: 4.6 | J35: 97.7 | K35: 8 | L35: 67 | M35: 78.5
A36: 291 | B36: Male | C36: Masters | D36: No | E36: No | F36: No | G36: C | H36: 45527 | I36: 2.3 | J36: 82.3 | K36: 5 | L36: 87.6 | M36: 79.6
A37: 749 | B37: Male | C37: Masters | D37: No | E37: Yes | F37: Yes | G37: D | I37: 0.6 | J37: 74.5 | K37: 7.9 | L37: 82.9 | M37: 66.4
A38: 249 | B38: Male | C38: PhD | D38: Yes | E38: Yes | F38: Yes | G38: F | H38: 45143 | I38: 1.4 | J38: 76.2 | K38: 5.8 | L38: 67 | M38: 57.2
A39: 638 | B39: Female | D39: No | E39: Yes | F39: Yes | G39: C | H39: 44953 | I39: 1.7 | J39: 82.2 | K39: 8.8 | L39: 80.6 | M39: 78.2
A40: 784 | B40: Male | C40: High School | D40: Yes | E40: Yes | F40: No | G40: B | H40: 45443 | I40: 5.8 | J40: 90.2 | K40: 8.7 | L40: 48 | M40: 83.4
...

Sheet Calidad
A1: student_id | B1: gender | C1: parental_education | D1: final_grade | E1: study_time_hours | F1: attendance_percent | G1: previous_grade | H1: final_exam_score | I1: en_rango | J1: nota_v | K1: estudio_v | L1: prev_v | M1: asist_v | O1: Resumen de calidad
A2: =Datos!A2 -> 781 | B2: =Datos!B2 -> Female | C2: =Datos!C2 -> Masters | D2: =Datos!G2 -> A | E2: =Datos!I2 -> 6.3 | F2: =Datos!J2 -> 97.4 | G2: =Datos!L2 -> 92.7 | H2: =Datos!M2 -> 100 | I2: =AND(E2>=0,E2<=12,F2>=0,F2<=100,G2>=0,G2<=100,H2>=0,H2<=100) -> TRUE | J2: =IF(I2,H2,"") -> 100 | K2: =IF(I2,E2,"") -> 6.3 | L2: =IF(I2,G2,"") -> 92.7 | M2: =IF(I2,F2,"") -> 97.4 | O2: Filas totales | P2: =COUNT($A$2:$A$961) -> 960
A3: =Datos!A3 -> 543 | B3: =Datos!B3 -> Female | C3: =Datos!C3 -> PhD | D3: =Datos!G3 -> F | E3: =Datos!I3 -> 2 | F3: =Datos!J3 -> 74.8 | G3: =Datos!L3 -> 48.3 | H3: =Datos!M3 -> 56.6 | I3: =AND(E3>=0,E3<=12,F3>=0,F3<=100,G3>=0,G3<=100,H3>=0,H3<=100) -> TRUE | J3: =IF(I3,H3,"") -> 56.6 | K3: =IF(I3,E3,"") -> 2 | L3: =IF(I3,G3,"") -> 48.3 | M3: =IF(I3,F3,"") -> 74.8 | O3: Filas válidas (en rango) | P3: =SUMPRODUCT(--($I$2:$I$961)) -> 956
A4: =Datos!A4 -> 34 | B4: =Datos!B4 -> Female | C4: =Datos!C4 -> Bachelors | D4: =Datos!G4 -> C | E4: =Datos!I4 -> 4.7 | F4: =Datos!J4 -> 92.3 | G4: =Datos!L4 -> 62.8 | H4: =Datos!M4 -> 74.2 | I4: =AND(E4>=0,E4<=12,F4>=0,F4<=100,G4>=0,G4<=100,H4>=0,H4<=100) -> TRUE | J4: =IF(I4,H4,"") -> 74.2 | K4: =IF(I4,E4,"") -> 4.7 | L4: =IF(I4,G4,"") -> 62.8 | M4: =IF(I4,F4,"") -> 92.3 | O4: Filas fuera de rango | P4: =P2-P3 -> 4
A5: =Datos!A5 -> 459 | B5: =Datos!B5 -> Female | C5: =Datos!C5 -> Masters | D5: =Datos!G5 -> C | E5: =Datos!I5 -> 3.3 | F5: =Datos!J5 -> 82.9 | G5: =Datos!L5 -> 77.6 | H5: =Datos!M5 -> 74.8 | I5: =AND(E5>=0,E5<=12,F5>=0,F5<=100,G5>=0,G5<=100,H5>=0,H5<=100) -> TRUE | J5: =IF(I5,H5,"") -> 74.8 | K5: =IF(I5,E5,"") -> 3.3 | L5: =IF(I5,G5,"") -> 77.6 | M5: =IF(I5,F5,"") -> 82.9 | O5: Nulos en parental_education | P5: =COUNTBLANK(Datos!$C$2:$C$961) -> 168
A6: =Datos!A6 -> 100 | B6: =Datos!B6 -> Male | C6: =Datos!C6 -> Masters | D6: =Datos!G6 -> C | E6: =Datos!I6 -> 6.2 | F6: =Datos!J6 -> 74.7 | G6: =Datos!L6 -> 50.6 | H6: =Datos!M6 -> 76 | I6: =AND(E6>=0,E6<=12,F6>=0,F6<=100,G6>=0,G6<=100,H6>=0,H6<=100) -> TRUE | J6: =IF(I6,H6,"") -> 76 | K6: =IF(I6,E6,"") -> 6.2 | L6: =IF(I6,G6,"") -> 50.6 | M6: =IF(I6,F6,"") -> 74.7 | O6: Nulos en Internet_Access | P6: =COUNTBLANK(Datos!$D$2:$D$961) -> 43
A7: =Datos!A7 -> 311 | B7: =Datos!B7 -> Male | C7: =Datos!C7 -> PhD | D7: =Datos!G7 -> A | E7: =Datos!I7 -> 6 | F7: =Datos!J7 -> 85.3 | G7: =Datos!L7 -> 94.9 | H7: =Datos!M7 -> 100 | I7: =AND(E7>=0,E7<=12,F7>=0,F7<=100,G7>=0,G7<=100,H7>=0,H7<=100) -> TRUE | J7: =IF(I7,H7,"") -> 100 | K7: =IF(I7,E7,"") -> 6 | L7: =IF(I7,G7,"") -> 94.9 | M7: =IF(I7,F7,"") -> 85.3 | O7: Nulos en enrollment_date | P7: =COUNTBLANK(Datos!$H$2:$H$961) -> 74
A8: =Datos!A8 -> 756 | B8: =Datos!B8 -> Male | C8: =Datos!C8 -> High School | D8: =Datos!G8 -> D | E8: =Datos!I8 -> 1.2 | F8: =Datos!J8 -> 82.6 | G8: =Datos!L8 -> 93.1 | H8: =Datos!M8 -> 65.8 | I8: =AND(E8>=0,E8<=12,F8>=0,F8<=100,G8>=0,G8<=100,H8>=0,H8<=100) -> TRUE | J8: =IF(I8,H8,"") -> 65.8 | K8: =IF(I8,E8,"") -> 1.2 | L8: =IF(I8,G8,"") -> 93.1 | M8: =IF(I8,F8,"") -> 82.6
A9: =Datos!A9 -> 184 | B9: =Datos!B9 -> Female | C9: =Datos!C9 -> High School | D9: =Datos!G9 -> C | E9: =Datos!I9 -> 2.3 | F9: =Datos!J9 -> 73.9 | G9: =Datos!L9 -> 85.8 | H9: =Datos!M9 -> 70.2 | I9: =AND(E9>=0,E9<=12,F9>=0,F9<=100,G9>=0,G9<=100,H9>=0,H9<=100) -> TRUE | J9: =IF(I9,H9,"") -> 70.2 | K9: =IF(I9,E9,"") -> 2.3 | L9: =IF(I9,G9,"") -> 85.8 | M9: =IF(I9,F9,"") -> 73.9
A10: =Datos!A10 -> 323 | B10: =Datos!B10 -> Male | C10: =Datos!C10 -> High School | D10: =Datos!G10 -> B | E10: =Datos!I10 -> 7 | F10: =Datos!J10 -> 78.3 | G10: =Datos!L10 -> 69.1 | H10: =Datos!M10 -> 83.4 | I10: =AND(E10>=0,E10<=12,F10>=0,F10<=100,G10>=0,G10<=100,H10>=0,H10<=100) -> TRUE | J10: =IF(I10,H10,"") -> 83.4 | K10: =IF(I10,E10,"") -> 7 | L10: =IF(I10,G10,"") -> 69.1 | M10: =IF(I10,F10,"") -> 78.3 | O10: Nota: una fila con algún valor imposible (nota, %, horas fuera de rango) se marca en_rango=FALSE y se excluye del análisis.
A11: =Datos!A11 -> 174 | B11: =Datos!B11 -> Female | C11: =Datos!C11 -> PhD | D11: =Datos!G11 -> D | E11: =Datos!I11 -> 4.5 | F11: =Datos!J11 -> 96.1 | G11: =Datos!L11 -> 35.9 | H11: =Datos!M11 -> 61 | I11: =AND(E11>=0,E11<=12,F11>=0,F11<=100,G11>=0,G11<=100,H11>=0,H11<=100) -> TRUE | J11: =IF(I11,H11,"") -> 61 | K11: =IF(I11,E11,"") -> 4.5 | L11: =IF(I11,G11,"") -> 35.9 | M11: =IF(I11,F11,"") -> 96.1
A12: =Datos!A12 -> 355 | B12: =Datos!B12 -> Male | C12: =Datos!C12 -> Bachelors | D12: =Datos!G12 -> B | E12: =Datos!I12 -> 5 | F12: =Datos!J12 -> 87.7 | G12: =Datos!L12 -> 90.9 | H12: =Datos!M12 -> 87.8 | I12: =AND(E12>=0,E12<=12,F12>=0,F12<=100,G12>=0,G12<=100,H12>=0,H12<=100) -> TRUE | J12: =IF(I12,H12,"") -> 87.8 | K12: =IF(I12,E12,"") -> 5 | L12: =IF(I12,G12,"") -> 90.9 | M12: =IF(I12,F12,"") -> 87.7
A13: =Datos!A13 -> 647 | B13: =Datos!B13 -> Male | C13: =Datos!C13 -> Bachelors | D13: =Datos!G13 -> D | E13: =Datos!I13 -> 5.6 | F13: =Datos!J13 -> 88.5 | G13: =Datos!L13 -> 40.8 | H13: =Datos!M13 -> 61.5 | I13: =AND(E13>=0,E13<=12,F13>=0,F13<=100,G13>=0,G13<=100,H13>=0,H13<=100) -> TRUE | J13: =IF(I13,H13,"") -> 61.5 | K13: =IF(I13,E13,"") -> 5.6 | L13: =IF(I13,G13,"") -> 40.8 | M13: =IF(I13,F13,"") -> 88.5
A14: =Datos!A14 -> 868 | B14: =Datos!B14 -> Female | C14: =Datos!C14 -> Bachelors | D14: =Datos!G14 -> B | E14: =Datos!I14 -> 2.6 | F14: =Datos!J14 -> 73.9 | G14: =Datos!L14 -> 83.3 | H14: =Datos!M14 -> 73 | I14: =AND(E14>=0,E14<=12,F14>=0,F14<=100,G14>=0,G14<=100,H14>=0,H14<=100) -> TRUE | J14: =IF(I14,H14,"") -> 73 | K14: =IF(I14,E14,"") -> 2.6 | L14: =IF(I14,G14,"") -> 83.3 | M14: =IF(I14,F14,"") -> 73.9
A15: =Datos!A15 -> 344 | B15: =Datos!B15 -> Male | C15: =Datos!C15 -> PhD | D15: =Datos!G15 -> D | E15: =Datos!I15 -> 3.5 | F15: =Datos!J15 -> 66.7 | G15: =Datos!L15 -> 92.2 | H15: =Datos!M15 -> 74.1 | I15: =AND(E15>=0,E15<=12,F15>=0,F15<=100,G15>=0,G15<=100,H15>=0,H15<=100) -> TRUE | J15: =IF(I15,H15,"") -> 74.1 | K15: =IF(I15,E15,"") -> 3.5 | L15: =IF(I15,G15,"") -> 92.2 | M15: =IF(I15,F15,"") -> 66.7
A16: =Datos!A16 -> 125 | B16: =Datos!B16 -> Male | C16: =Datos!C16 -> PhD | D16: =Datos!G16 -> B | E16: =Datos!I16 -> 4.8 | F16: =Datos!J16 -> 68.9 | G16: =Datos!L16 -> 65 | H16: =Datos!M16 -> 82.7 | I16: =AND(E16>=0,E16<=12,F16>=0,F16<=100,G16>=0,G16<=100,H16>=0,H16<=100) -> TRUE | J16: =IF(I16,H16,"") -> 82.7 | K16: =IF(I16,E16,"") -> 4.8 | L16: =IF(I16,G16,"") -> 65 | M16: =IF(I16,F16,"") -> 68.9
A17: =Datos!A17 -> 673 | B17: =Datos!B17 -> Female | C17: =Datos!C17 -> High School | D17: =Datos!G17 -> C | E17: =Datos!I17 -> 6.2 | F17: =Datos!J17 -> 82 | G17: =Datos!L17 -> 38 | H17: =Datos!M17 -> 72.9 | I17: =AND(E17>=0,E17<=12,F17>=0,F17<=100,G17>=0,G17<=100,H17>=0,H17<=100) -> TRUE | J17: =IF(I17,H17,"") -> 72.9 | K17: =IF(I17,E17,"") -> 6.2 | L17: =IF(I17,G17,"") -> 38 | M17: =IF(I17,F17,"") -> 82
A18: =Datos!A18 -> 610 | B18: =Datos!B18 -> Female | C18: =Datos!C18 -> 0 | D18: =Datos!G18 -> C | E18: =Datos!I18 -> 6.1 | F18: =Datos!J18 -> 73.8 | G18: =Datos!L18 -> 45.3 | H18: =Datos!M18 -> 79.8 | I18: =AND(E18>=0,E18<=12,F18>=0,F18<=100,G18>=0,G18<=100,H18>=0,H18<=100) -> TRUE | J18: =IF(I18,H18,"") -> 79.8 | K18: =IF(I18,E18,"") -> 6.1 | L18: =IF(I18,G18,"") -> 45.3 | M18: =IF(I18,F18,"") -> 73.8
A19: =Datos!A19 -> 812 | B19: =Datos!B19 -> Male | C19: =Datos!C19 -> PhD | D19: =Datos!G19 -> C | E19: =Datos!I19 -> 3.5 | F19: =Datos!J19 -> 76.4 | G19: =Datos!L19 -> 78.8 | H19: =Datos!M19 -> 74.2 | I19: =AND(E19>=0,E19<=12,F19>=0,F19<=100,G19>=0,G19<=100,H19>=0,H19<=100) -> TRUE | J19: =IF(I19,H19,"") -> 74.2 | K19: =IF(I19,E19,"") -> 3.5 | L19: =IF(I19,G19,"") -> 78.8 | M19: =IF(I19,F19,"") -> 76.4
A20: =Datos!A20 -> 574 | B20: =Datos!B20 -> Male | C20: =Datos!C20 -> 0 | D20: =Datos!G20 -> F | E20: =Datos!I20 -> 2.7 | F20: =Datos!J20 -> 90.1 | G20: =Datos!L20 -> 37.9 | H20: =Datos!M20 -> 57.8 | I20: =AND(E20>=0,E20<=12,F20>=0,F20<=100,G20>=0,G20<=100,H20>=0,H20<=100) -> TRUE | J20: =IF(I20,H20,"") -> 57.8 | K20: =IF(I20,E20,"") -> 2.7 | L20: =IF(I20,G20,"") -> 37.9 | M20: =IF(I20,F20,"") -> 90.1
A21: =Datos!A21 -> 547 | B21: =Datos!B21 -> Male | C21: =Datos!C21 -> High School | D21: =Datos!G21 -> C | E21: =Datos!I21 -> 1.9 | F21: =Datos!J21 -> 82 | G21: =Datos!L21 -> 82.3 | H21: =Datos!M21 -> 74.1 | I21: =AND(E21>=0,E21<=12,F21>=0,F21<=100,G21>=0,G21<=100,H21>=0,H21<=100) -> TRUE | J21: =IF(I21,H21,"") -> 74.1 | K21: =IF(I21,E21,"") -> 1.9 | L21: =IF(I21,G21,"") -> 82.3 | M21: =IF(I21,F21,"") -> 82
A22: =Datos!A22 -> 942 | B22: =Datos!B22 -> Female | C22: =Datos!C22 -> 0 | D22: =Datos!G22 -> B | E22: =Datos!I22 -> 5.7 | F22: =Datos!J22 -> 89.8 | G22: =Datos!L22 -> 71.3 | H22: =Datos!M22 -> 80.5 | I22: =AND(E22>=0,E22<=12,F22>=0,F22<=100,G22>=0,G22<=100,H22>=0,H22<=100) -> TRUE | J22: =IF(I22,H22,"") -> 80.5 | K22: =IF(I22,E22,"") -> 5.7 | L22: =IF(I22,G22,"") -> 71.3 | M22: =IF(I22,F22,"") -> 89.8
... A961: =Datos!A961 -> 415 | B961: =Datos!B961 -> Female | C961: =Datos!C961 -> 0 | D961: =Datos!G961 -> B | E961: =Datos!I961 -> 6.8 | F961: =Datos!J961 -> 73.9 | G961: =Datos!L961 -> 46.3 | H961: =Datos!M961 -> 82.6 | I961: =AND(E961>=0,E961<=12,F961>=0,F961<=100,G961>=0,G961<=100,H961>=0,H961<=100) -> TRUE | J961: =IF(I961,H961,"") -> 82.6 | K961: =IF(I961,E961,"") -> 6.8 | L961: =IF(I961,G961,"") -> 46.3 | M961: =IF(I961,F961,"") -> 73.9

Sheet Univariado
A1: Estadísticas de la nota del examen final (solo filas válidas)
A2: Conteo | B2: =COUNT(Calidad!$J$2:$J$961) -> 956
A3: Promedio | B3: =AVERAGE(Calidad!$J$2:$J$961) -> 73.578556
A4: Mínimo | B4: =MIN(Calidad!$J$2:$J$961) -> 42.8
A5: Máximo | B5: =MAX(Calidad!$J$2:$J$961) -> 100
A6: Desviación estándar | B6: =STDEV(Calidad!$J$2:$J$961) -> 12.022846
A7: Q1 | B7: =QUARTILE(Calidad!$J$2:$J$961,1) -> 65
A8: Mediana | B8: =MEDIAN(Calidad!$J$2:$J$961) -> 73.7
A9: Q3 | B9: =QUARTILE(Calidad!$J$2:$J$961,3) -> 81.9
A10: Límite inferior outlier (Q1-1.5·RIC) | B10: =B7-1.5*(B9-B7) -> 39.65
A11: Límite superior outlier (Q3+1.5·RIC) | B11: =B9+1.5*(B9-B7) -> 107.25
A13: Nota final | B13: Estudiantes
A14: A | B14: =COUNTIF(Calidad!$D$2:$D$961,A14) -> 98
A15: B | B15: =COUNTIF(Calidad!$D$2:$D$961,A15) -> 207
A16: C | B16: =COUNTIF(Calidad!$D$2:$D$961,A16) -> 292
A17: D | B17: =COUNTIF(Calidad!$D$2:$D$961,A17) -> 233
A18: F | B18: =COUNTIF(Calidad!$D$2:$D$961,A18) -> 130

Sheet Bivariado
A1: Nota promedio según educación de los padres
A2: Educación | B2: Nota promedio
A3: High School | B3: =IFERROR(AVERAGEIF(Calidad!$C$2:$C$961,A3,Calidad!$J$2:$J$961),"") -> 73.85045
A4: Bachelors | B4: =IFERROR(AVERAGEIF(Calidad!$C$2:$C$961,A4,Calidad!$J$2:$J$961),"") -> 72.812931
A5: Masters | B5: =IFERROR(AVERAGEIF(Calidad!$C$2:$C$961,A5,Calidad!$J$2:$J$961),"") -> 74.190323
A6: PhD | B6: =IFERROR(AVERAGEIF(Calidad!$C$2:$C$961,A6,Calidad!$J$2:$J$961),"") -> 74.47095
A7: (sin dato de educación se excluye)
A9: Nota promedio por género
A10: Género | B10: Nota promedio
A11: Female | B11: =AVERAGEIF(Calidad!$B$2:$B$961,A11,Calidad!$J$2:$J$961) -> 73.259355
A12: Male | B12: =AVERAGEIF(Calidad!$B$2:$B$961,A12,Calidad!$J$2:$J$961) -> 73.880855
A15: Dispersión: horas de estudio vs nota final

Sheet Correlacion
A1: Correlación con la nota final
A2: Variable | B2: Coef. correlación (r)
A3: Horas de estudio | B3: =CORREL(Calidad!$K$2:$K$961,Calidad!$J$2:$J$961) -> 0.62842193
A4: Nota previa | B4: =CORREL(Calidad!$L$2:$L$961,Calidad!$J$2:$J$961) -> 0.41504695
A5: Asistencia (%) | B5: =CORREL(Calidad!$M$2:$M$961,Calidad!$J$2:$J$961) -> 0.20511004
A7: Interpretación (horas de estudio) | B7: =IF(ABS(B3)>=0.7,"Correlación fuerte",IF(ABS(B3)>=0.3,"Correlación moderada","Correlación débil"))&IF(B3>=0," positiva."," negativa.") -> Correlación moderada positiva.
A9: Recuerda: correlación no implica causalidad.

Sheet Conclusiones
A1: Conclusiones
A2: Hallazgos del análisis exploratorio de la base de rendimiento estudiantil.
A4: Hallazgo 1 | B4: Las horas de estudio son la variable que más se relaciona con la nota final (r ≈ 0.63, correlación moderada). Los que estudian más tienden a sacar mejor nota; le sigue la nota previa (r ≈ 0.42).
A5: Hallazgo 2 | B5: La educación de los padres casi no cambia la nota promedio (todas las categorías quedan entre 73 y 74.5), así que no parece un factor importante aquí. El género tampoco marca diferencia.
A6: Hallazgo 3 (calidad) | B6: Quedaron valores imposibles de la limpieza: una nota de 999, asistencia de 150% y sueño de 25 h. Se excluyen en la hoja Calidad, pero habría que corregirlos en el origen.
A7: Hipótesis a validar | B7: Si un estudiante aumenta sus horas de estudio, debería subir su nota final. Habría que comprobarlo con un modelo, no solo con la correlación.
